Workbook

Sheet 1.1) Рег. уровень_безопис
A1: Страна | B1: Год | C1: Дата | D1: Состав | E1: Лидер | F1: Тип события | G1: Место проведения | H1: Текст | I1: Ссылка | J1: Кол-во упоминаний | K1: Кол-во_ сюжет_транспортно_логистический | L1: Кол-во_ сюжет_экономический | M1: Кол-во_сюжет_геополитический | N1: Кол-во_Сюжет_цивилизационный | O1: Кол-во_сюжет_институциональный | P1: Кол-во_сюжет_социально_гуманитарный
J2: евразий- | K2: "автомобильный транспорт", "железнодорожный транспорт", "авиасообщение", "морской транспорт", "мультимодальный транспорт", "транспортная инфраструктура", "железная дорога", "пункт пропуска", "логистика", "грузоперевозки", "транзит", "транзитный потенциал", "грузооборот", "контейнерные перевозки", "связанность", "транспортная связанность", "единое транспортное пространство", "транспортный коридор", "шёлковый путь", "шелковый путь", "север-юг", "транспортный маршрут", "транспортные тарифы", "либерализация перевозок", "цифровая логистика", "умная граница", "навигационные пломбы", "логистический хаб", "сухой порт", "контейнерный терминал" | L2: "рынок", "общий рынок", "единый рынок", "ёмкий рынок", "торговля", "товарооборот", "экспорт", "импорт", "поставки", "инвестиции", "инвесторы", "капитал", "капиталовложения", "ввп", "экономический рост", "рост экономики", "развитие экономики", "конкурентоспособность", "барьеры", "ограничения", "пошлины", "тарифы", "нетарифные барьеры", "производительность", "добавленная стоимость", "промышленность", "отрасли", "бизнес", "предприниматели", "компании", "предприятия", "интеграция рынков", "экономическая интеграция", "экономический союз" | M2: "центр силы", "полюс", "полюс роста", "центр мирового", "центр регионального", "многополярный мир", "многополярность", "суверенитет", "независимость", "стратегическая автономия", "геополитика", "геополитический", "геополитические интересы", "стратегические интересы", "мировой порядок", "международная система", "архитектура безопасности", "влияние", "лидерство", "позиционирование", "роль в мире", "баланс", "противостояние" | N2: "цивилизация", "цивилизационный", "евразийская цивилизация", "общая история", "историческое единство", "исторические корни", "наследие", "культура", "культурные традиции", "духовные ценности", "духовность", "идентичность", "общая идентичность", "общность", "традиционные ценности", "общие ценности", "менталитет", "особый путь", "свой путь развития", "путь наших народов", "братские народы", "многовековые связи", "историческое братство" | O2: "договор", "соглашение", "ратификация", "ратифицирован", "протокол", "решение", "документ", "орган", "комиссия", "совет", "комитет", "рабочая группа", "институт", "институты союза", "регламент", "процедура", "механизм", "инструменты", "нормативная база", "дорожная карта", "дорожные карты", "программа", "план мероприятий", "компетенции", "полномочия", "юрисдикция", "порядок председательства", "распределение голосов", "структура органов", "правовая база", "договорно-правовая база", "договорно‑правовая база", "юрисдикция суда" | P2: "граждане", "наши граждане", "люди", "население", "трудовая миграция", "мигранты", "условия труда", "социальные гарантии", "образование", "университеты", "студенты", "академические обмены", "наука", "научное сотрудничество", "исследования", "культура", "культурные обмены", "язык", "гуманитарные проекты", "здравоохранение", "медицина", "фармацевтика", "социальная защита", "пенсии", "социальные выплаты", "уровень жизни", "качество жизни", "молодежь", "молодёжные программы", "молодежные программы", "студенческие программы"
A4: Россия | B4: 2014 | C4: 23 декабря | E4: Путин | F4: заседание ВЕЭС | G4: Москва | H4: В.Путин: Уважаемые коллеги, добрый день! Мы проводим заключительное в этом году заседание Высшего Евразийского экономического совета. В углублении интеграции достигнуты хорошие, масштабные результаты. В сжатые сроки завершена подготовка Договора о создании Евразийского экономического союза. Мы подписали его в мае на саммите в Астане, а уже к нашей встрече в октябре в Минске Договор был ратифицирован парламентами России, Белоруссии и Казахстана и вступит в действие с 1 января 2015 года. Таким образом, Евразийский экономический союз заработает в полную силу. Как мы уже неоднократно говорили, будет создан общий ёмкий рынок с более чем 170 миллионами потребителей, обеспечена свобода передвижения товаров, услуг, капитала и рабочей силы. Бизнес получит возможность вести дела по универсальным прозрачным правилам международной торговли, основанным в том числе на принципах Всемирной торговой организации. Взаимная выгода от участия в интеграционных процессах очевидна. Успешная деятельность Таможенного союза, который мы создали в 2011 году, наглядно это подтвердила. Экономические связи внутри «тройки» укрепились и количественно, и качественно. Товарооборот вырос на 50 процентов. Что касается качества, то улучшилась структура взаимной торговли – за счёт повышения доли товаров с высокой добавленной стоимостью. Начало функционирования Евразийского союза означает переход на более продвинутый этап интеграции. Убеждён, это придаст дополнительный импульс развитию экономик наших государств. Союз станет мощным центром роста всего региона, увеличатся торговые и инвестиционные потоки, будут укрепляться деловые связи и повысится благосостояние наших граждан. Реализуемый нами интеграционный проект уникален не только по масштабу и содержанию, но и по духу. Он основан на принципах равноправия, доверия, взаимного уважения и учёта интересов друг друга. При этом его участники не отказываются от государственного суверенитета и сохраняют свою национальную самобытность. Мы стремимся находить взаимоприемлемые развязки и компромиссы по самым различным вопросам, руководствуемся принципом консенсуса при принятии основополагающих решений. Наши страны в равной степени представлены в руководящих органах и Суде Союза. Всё это делает евразийскую интеграцию привлекательной для соседей и партнёров по СНГ. Два месяца назад в Минске мы заключили Договор о присоединении к Союзу Армении. Процедуры его ратификации завершены, так что со 2 января будущего года Армения станет полноценным членом нашего объединения. С 1 января 2015 года Евразийский экономический союз заработает в полную силу. Будет создан общий ёмкий рынок, обеспечена свобода передвижения товаров, услуг, капитала и рабочей силы. Бизнес получит возможность вести дела по универсальным правилам международной торговли. Сегодня подпишем Договор о вступлении в Евразийский союз Киргизии. Киргизские друзья совместно с правительствами «тройки», Евразийской комиссией прилагают серьёзные усилия для адаптации национального законодательства к требованиям Таможенного союза и Единого экономического пространства. Реализована большая часть соответствующих дорожных карт. Важно не снижать темпов и сообща завершить эту работу. Интерес к наращиванию сотрудничества с Евразийским союзом проявляют и страны из других регионов. В финальную стадию вступила подготовка проекта соглашения о свободной торговле с Вьетнамом. Аналогичные договорённости прорабатываются с Турцией, Индией, Израилем. Совсем недавно, я коллегам сейчас об этом рассказывал, в ходе поездки в Узбекистан договорились с Президентом Узбекистана о том, что начнём работу, создадим рабочую группу по работе над договором о зоне свободной торговли между нашим объединением и Узбекистаном. Готовятся меморандумы о взаимопонимании с АСЕАН и МЕРКОСУР. Уверен, интересам нашего объединения одинаково отвечает расширение связей со всеми странами и организациями как на Востоке, так и на Западе – на основе равноправия и взаимной выгоды. Суммируя, хочу подчеркнуть, что наше интеграционное взаимодействие успешно развивается, налицо его конкретные осязаемые результаты. Однако останавливаться на достигнутом, конечно, нельзя, впереди новые большие задачи. Предстоит на практике наладить стабильное и эффективное функционирование Евразийского союза, продолжить работу по укреплению его институциональных основ. Ряд важных решений в этом направлении мы примем уже сегодня. В их числе договорённость о порядке председательства в нашем объединении. Среди других приоритетов вижу необходимость повышения конкурентоспособности и инвестиционной привлекательности Евразийского союза, запуск перспективных совместных проектов и создание высокотехнологичных рабочих мест в нефтегазовом комплексе, металлургии, химической промышленности, авиа- и машиностроении, космической отрасли. Нужно снимать остающиеся барьеры, ограничивающие свободу передвижения товаров, услуг, капиталов, рабочей силы. Предстоит реализовать планы по формированию с 2016 года общего рынка фармацевтической и медицинской продукции. Шагом к этому станет сегодняшнее наше решение об обороте лекарственных средств и медицинских изделий. Мы также утвердим перечень секторов услуг, в которых единый рынок начнёт функционировать уже с 1 января 2015 года. От этого выиграют строители, предприятия оптовой и розничной торговли, туристического бизнеса. Важно также не затягивать с взаимным признанием лицензий на ведение этих видов деятельности наших стран, чтобы наши компании уже с первых дней работы Союза могли в полной мере воспользоваться преимуществами интеграции. Рассчитываю, что наше заседание по традиции пройдёт в деловой и конструктивной атмосфере. Благодарю вас за внимание. | I4: http://www.kremlin.ru/events/president/transcripts/47311 | J4: 11 | K4: 0 | L4: 19 | M4: 1 | N4: 0 | O4: 14 | P4: 0
A5: Россия | B5: 2014 | C5: 10 октября | E5: Путин | F5: заседание ВЕЭС | G5: Минск | H5: В.ПУТИН: Уважаемые коллеги! Россия, Белоруссия и Казахстан уверенно идут по пути углубления евразийской интеграции. Парламенты наших стран к встрече в Минске синхронно ратифицировали Договор о Евразийском экономическом союзе. Как и договаривались, Евразийский экономический союз заработает с 1 января 2015 года. Мы переходим на новую, более высокую ступень интеграции, что позволит эффективнее решать задачи модернизации экономик наших стран и повышения их конкурентоспособности. Будет проводиться согласованная политика в ключевых отраслях промышленности, энергетики и сельского хозяйства, будут устранены барьеры, ограничивающие свободу передвижения товаров, услуг, капитала, рабочей силы. Создаваемый общий евразийский рынок начнёт функционировать по универсальным, прозрачным и понятным правилам, основанным на нормах и принципах Всемирной торговой организации. Отмечу, наш интеграционный проект уже приносит практическую отдачу. В рамках Таможенного союза с 1 июля 2011 года товарооборот вырос на 50 процентов, превысив отметку в 64 миллиарда долларов. Улучшилась структура взаимной торговли: продукция с высокой степенью переработки стала постепенно замещать сырьевые товары, [её доля] увеличилась существенным образом, а сырьевых товаров – снизилась с 40 до 28,9 процента. Весьма важно, что курс на тесную интеграцию пользуется широкой общественной поддержкой в наших странах. По данным социологических опросов, которые проведены Евразийским банком развития, деятельность Таможенного союза положительно оценивается 79 процентами граждан Российской Федерации, 68 процентами граждан Белоруссии и 84 процентами граждан Казахстана. Столь высокий уровень доверия необходимо оправдать достижением ощутимых результатов, а именно дальнейшим повышением качества жизни и благополучия населения наших стран. Уважаемые коллеги, в ходе нынешнего заседания мы подпишем Договор о присоединении Армении к Евразийскому экономическому союзу. Рассчитываем, что законодатели наших государств также слаженно одобрят его до конца года. На наш взгляд, Армения готова к работе в Евразийском экономическом союзе на равных с Россией, Белоруссией и Казахстаном. За относительно короткий срок, с осени 2013 года, наши армянские друзья подтянули экономическое регулирование под общие стандарты, привели национальное законодательство в соответствие с нормами нашего интеграционного объединения. Надеемся, что уже в первые год-два после присоединения Армении мы увидим положительный макроэкономический эффект. Товарооборот «тройки» с Арменией и так рос высокими темпами, прибавляя до 10 процентов ежегодно. После снятия таможенных и административных барьеров такая позитивная тенденция, надеюсь, ещё больше укрепится. Должны улучшиться и другие ключевые индикаторы: валовой продукт, потребительский спрос, реальные доходы населения и занятость. Сегодня предстоит также утвердить дорожную карту интеграции Киргизии в Единое экономическое пространство. Она позволит дополнить принятый ранее, на майском саммите в Астане, план по адаптации киргизской экономики к стандартам Таможенного союза. Мы понимаем, что киргизским коллегам необходимо содействие как в совершенствовании внутреннего законодательства, так и в проведении структурных преобразований. Россия такую помощь уже оказывает в рамках двусторонних договорённостей. Рассчитываем, что мы сможем объединить наши усилия с белорусскими и казахстанскими партнёрами. Помимо Армении и Киргизии интерес к сотрудничеству с Евразийским экономическим союзом проявляют и другие государства и региональные организации. В Евразийскую экономическую комиссию уже поступило несколько десятков предложений об установлении преференциальных режимов торговли. Этим так называемым внешним досье, как представляется, следует заниматься более активно. В частности, важно как можно скорее завершить переговоры по проекту соглашения о зоне свободной торговли с Вьетнамом, интенсифицировать экспертные консультации с Израилем, Индией, Египтом, продолжить развивать диалог с Южноамериканским общим рынком (МЕРКОСУР), Ассоциацией государств Юго-Восточной Азии (АСЕАН). Отдельно хочу сказать об отношениях с нашим соседом, Украиной, в контексте подписанного ею Соглашения об ассоциации с ЕС. В августе здесь, в Минске, главы государств «тройки» встретились с украинским Президентом и представителями Евросоюза. И Киев, и Брюссель прислушались к нашим аргументам, приняли решение отсрочить применение экономического блока Соглашения об ассоциации до 31 декабря 2015 года. Теперь появилась возможность откорректировать те положения упомянутого Соглашения, реализация которых могла бы нанести существенный ущерб экономике Таможенного союза и нашим традиционным торговым связям с Украиной. Конечно, переговоры предстоят непростые, и нам необходимо выступать с солидарных позиций, чтобы убедить партнёров отказаться от противопоставления европейской и евразийской интеграции в пользу сопряжения обоих проектов. Уважаемые коллеги! Хотел бы вновь подчеркнуть, что значение евразийской интеграции в жизни наших государств объективно возрастает. Это требует от всех нас ещё более слаженных и скоординированных действий, важно не снижать набранного темпа работы. До конца года нам необходимо утвердить ещё около пятидесяти документов по некоторым организационным и финансовым вопросам деятельности Евразийского экономического союза. Предлагаю, уважаемые коллеги, провести следующее наше заседание в декабре в Москве, где мы могли бы завершить весь подготовительный процесс. Мы уже и с Нурсултаном Абишевичем Назарбаевым, и с Президентом Белоруссии Александром Григорьевичем Лукашенко об этом говорили, я хотел бы об этом сказать здесь официально, на нашей встрече. И хочу вас поблагодарить за внимание. Спасибо большое. | I5: https://kazakhstan.mid.ru/ru/press-centre/news/vstrecha_glav_gosudarstv_vysshego_evraziyskogo_ekonomicheskogo_soveta/ | J5: 12 | K5: 0 | L5: 6 | M5: 0 | N5: 0 | O5: 8 | P5: 0
A6: Россия | B6: 2014 | C6: 5 марта | E6: Путин | F6: заседание ВЕЭС | G6: Московская область | H6: В.ПУТИН: Добрый день, уважаемые друзья, коллеги! Россия, Белоруссия и Казахстан последовательно продвигаются по пути интеграции, и сегодня мы в рамках Высшего Евразийского экономического совета на уровне глав государств поговорим о том, что происходит в этой сфере, куда мы двигаемся, каким темпом, выполняем ли мы все запланированные ранее шаги, все планы. Наша общая цель – перейти на новый, более высокий уровень взаимодействия и создать в начале 2015 года, как мы договаривались, Евразийский экономический союз. Для этого необходимо выдержать намеченные сроки и завершить к маю подготовку проекта договора. В соответствии с поручением, которое мы дали на предыдущем заседании в Москве (оно состоялось в декабре), правительства «тройки», Евразийская экономическая комиссия ускорили работу над текстом договора, он в деталях обсуждался и вчера в Астане на уровне вице-премьеров. Наш участник, это первый вице-премьер российского Правительства Игорь Шувалов, сегодня мне с утра уже докладывал об этих результатах. Институциональная часть договоров должна определить международно-правовой статус и организационные рамки будущего союза, закрепить основные принципы его деятельности. Функциональная, отраслевая часть будет регламентировать механизмы экономического взаимодействия. При этом важно гарантировать так называемые четыре свободы, то есть по обеспечению беспрепятственного перемещения товаров, услуг, капиталов и рабочей силы, зафиксировать конкретные обязательства по устранению изъятий и ограничений, сохраняющихся в Таможенном союзе и Едином экономическом пространстве. Союз надо наделить широким набором полномочий в сфере экономического регулирования. Это позволит проводить общую и согласованную политику в ключевых отраслях, повысить устойчивость и потенциал развития национальных экономик, обеспечит ёмкий единый рынок и приток дополнительных инвестиций. Евразийские интеграционные процессы уже приносят вполне конкретные результаты, конкретную отдачу. Несмотря на общее замедление темпов роста мировой экономики, мирового хозяйства, в 2013 году товарооборот в рамках тройки не только не снизился, а чуть-чуть всё-таки увеличился и составил 64,1 миллиарда долларов. При этом улучшается структура взаимной торговли, сокращается доля сырьевых ресурсов в экспортно-импортных операциях, причём это изменение идёт за счёт повышения технологической продукции, за счёт товаров с высокой добавленной стоимостью, – и изменения значительные. В общей структуре с 28,9 процента доля высокотехнологичной продукции увеличилась до 40 процентов. Интеграция создаёт предпосылки для равноправной конкуренции на рынке государств Таможенного союза. Расширяется потребительский спрос. Тем самым стимулируется инновационная активность наших компаний, производители более эффективно используют имеющиеся ресурсы. Приоритетным направлением интеграционного взаимодействия стал учёт интересов бизнес-сообщества. Евразийская экономическая комиссия наладила тесные сотрудничества с объединениями деловых кругов наших стран, консультируется с предпринимателями по вопросам совершенствования нормативной базы Таможенного союза и Единого экономического пространства. Я скажу больше, не просто консультируется: по сути, представители бизнес-кругов включены в этот процесс и являются соавторами всех этих документов. Евразийский интеграционный проект привлекает наших партнёров по СНГ. В наиболее продвинутой стадии находятся переговоры о подключении к нему и Армении, и Кыргызстана. С армянской стороной принят и успешно реализуется план мероприятий по адаптации к нормам и требованиям Таможенного союза и Единого экономического пространства. Поэтому считаем возможным перейти к подготовке проекта договора о присоединении Армении к будущему Евразийскому экономическому союзу. Конечно, нужно все минусы и плюсы здесь взвесить, причём для всех участников этого процесса. Важно продолжить и содействие Кыргызстану по присоединению. Необходимо вместе с нашими партнёрами утвердить дорожную карту дальнейших действий. Ключевой экономический партнёр Таможенного союза – Украина. Нас объединяют тесные промышленные и торговые связи. Украинцы входят в зону свободной торговли СНГ. Экстраординарная ситуация, сложившаяся на Украине, вызывает серьёзное беспокойство. Украинская экономика находится в тяжёлом, если не сказать тяжелейшем кризисе. Возможны негативные последствия и для рынка Таможенного союза. Поэтому нужно вместе подумать над тем, что бы предпринять в целях защиты наших производителей и экспортёров, а также проработать параметры дальнейшего взаимодействия с Украиной. Безусловно, нам нужно сделать всё, чтобы помочь нашим партнёрам выйти из той сложной ситуации, в которой они сегодня находятся. Мы, конечно, обсудим сегодня и другие аспекты, касающиеся ситуации вокруг Украины. Евразийское интеграционное объединение открыто к сотрудничеству со всеми государствами и уже приступило к формированию пакета соглашений о свободной торговле с рядом государств. Получено около 40 предложений о заключении таких договоров, в том числе от Европейской ассоциации свободной торговли: это Исландия Лихтенштейн, Норвегия, Швейцария, – от Вьетнама, Израиля, Индии, Чили, Перу. И в заключение подчеркну: Россия дорожит конструктивными, равноправными и открытыми отношениями, которые сложились в сфере экономики между нашими странами, высоко ценит достигнутые совместные результаты. Убеждён, евразийская экономическая интеграция открывает перед участниками этого проекта новые, уникальные возможности, которые могут и должны быть использованы на благо граждан наших стран. Я вас благодарю за внимание и хочу передать слово нашим сегодняшним гостям. Пожалуйста. А.ЛУКАШЕНКО: Уважаемые коллеги! Сегодня мы собрались, чтобы обсудить ход работы над проектом договора о Евразийском экономическом союзе. Учитывая, что Президент России очень подробно изложил ситуацию вокруг Единого экономического пространства, охарактеризовал направления нашей работы по формированию договора, я ограничусь только несколькими проблемами, которые надо решать. И изложу свою позицию с точки зрения Белоруссии, как мы это видим. Мы планировали собраться в середине марта. Но эксперты после работы в Астане нас подтолкнули к тому, чтобы мы решили ряд вопросов на нашем уровне, чтобы дать им возможность работать более активно. В противном случае, как они сказали, можем не успеть к середине этого года создать мощный правовой механизм нашего экономического союза. Поэтому мы перенесли немного эту встречу. Наверное, правильно сделали. Это даст возможность комиссии и специалистам пару недель уже иметь в резерве, для того чтобы подготовить договор к рассмотрению на высшем уровне. На предыдущей встрече в Москве нами определены вопросы для дополнительной проработки. Перед экспертами поставлена задача – завершить работу по их согласованию. Как меня информировали, в подготовке документов удалось продвинуться вперёд, но отдельные аспекты всё же требуют решения на нашем уровне, о чём я только что сказал. Надеюсь, что в ходе сегодняшней встречи нам удастся найти взаимоприемлемое решение, чтобы подписать договор в согласованные сроки. Мы не можем повторить тот печальный опыт, который был характерен для нас в рамках СНГ. Мы очень много говорили об СНГ. Говорили-говорили и заговорили. Люди ждали от нас шагов по формированию в рамках СНГ нормальных отношений и союза. Не получилось. И у людей очень большая настороженность, чтобы это не произошло с нашим Таможенным союзом и Единым экономическим пространством. У нас просто нет выбора и нет выхода: мы должны в заявленные сроки подготовить договор и в заявленные сроки его подписать. В противном случае нас люди не поймут. Хотел бы отметить два момента, принципиальных для Беларуси и, наверное, важных для всех наших стран. Во-первых, в нашем интеграционном проекте мы должны выйти на конкретные результаты. Таким результатом является завершение создания Таможенного союза без каких-либо ограничений и изъятий. В этом вопросе стороны продвинулись дальше всего. Фактически остались изъятия лишь по некоторым, однако весьма чувствительным товарам, включая алкоголь, табак, лекарства, нефть, газ. И нам необходимо принять по ним принципиальное решение. Однако появились подходы, когда отмену изъятий по товарам начали увязывать с отменой изъятий по услугам, капиталу, рабочей силе. Наша принципиальная позиция – создание Евразийского экономического союза должно базироваться на полномасштабном Таможенном союзе, без изъятий, в том числе без пошлин, количественных ограничений или чего-то другого. Свобода движения товаров должна стать примером для решения задач по реализации остальных трёх свобод. Без этого будущий экономический союз лишится прочного фундамента. Одновременно мы продолжаем целенаправленно работать над реализацией тех договорённостей, которые закреплены в базовых соглашениях Единого экономического пространства. Во-вторых, по проекту договора. Позиция белорусской стороны по отдельным положениям институциональной части договора была изложена в ходе нашей предыдущей встречи в Москве. Эксперты ведут работу по её согласованию. Думаю, нет необходимости возвращаться к этому вопросу и теперь. Функциональная часть договора, о которой только что говорил Президент России, совершенствуется, идёт работа. Хотя эта работа активизировалась, однако готовность проекта оценивается всё теми же экспертами примерно 70–80 процентами, о которых были проинформированы на нашей прошлой встрече. Сближения по наиболее чувствительным позициям для каждой из сторон практически не произошло, в том числе по формированию общего энергетического рынка, либерализации автомобильного транспортного рынка, доступу к газотранспортной системе, правилам субсидирования сельского хозяйства стороны постоянно выдвигают новые предложения, которые могут размыть уже имеющиеся договорённости. Поэтому предлагаю в нашей дальнейшей работе по проекту договора руководствоваться следующим подходом. Совершенствовать нормативно-правовую базу ЕЭП при согласии с предлагаемыми изменениями всех трёх сторон. Если же кто-то против, то включать в проект договора нормы соглашений ЕЭП в их неизменном состоянии, которые есть сегодня, чтобы не допустить отхода, отката назад, потому что по некоторым позициям эксперты нам говорят о том, что это уже происходит при обсуждении. В противном случае мы рискуем неоправданно затянуть процесс подготовки договора и, соответственно, начало работы Евразийского экономического союза. Вот два принципиальных момента, на наш взгляд, по которым мы должны принять решения и более активно двигаться в направлении создания нашей экономической системы, экономического союза. Будем откровенно говорить, события в мире нас очень активно подталкивают к тому, чтобы этот процесс ускорять. Нам, наверное, меньше надо посматривать по сторонам, а заниматься своими делами, своими государствами, тогда нас и уважать будут, и ценить будут. Благодарю. | I6: https://eccis.org/news/2830/suzet-5-marta-v-moskve-sostoalos-zasedanie-vyssego-evrazijskogo-ekonomiceskogo-soveta | J6: 12 | K6: 0 | L6: 13 | M6: 0 | N6: 0 | O6: 30 | P6: 2
A7: Россия | B7: 2015 | C7: 8 мая | E7: Путин | F7: заседание ВЕЭС | G7: Москва | H7: В.Путин: Уважаемые коллеги, добрый день! Наше заседание – первое с начала работы Евразийского экономического союза. Я очень рад отметить, что большинство принятых решений по запуску евразийского интеграционного проекта реализовано в полной мере и в сроки, о которых мы договаривались. На мировой арене появилось новое экономическое объединение с едиными правилами движения товаров, услуг, капитала, трудовых ресурсов. Со 2 января полноправным членом союза стала Армения, и уже приняты решения – надеюсь, после ратификации всё это вступит в силу – по присоединению Киргизии в полномасштабном формате. Важно, что у всех участников Евразийского союза есть настрой на углубление интеграции. Более тесные торговые инвестиционные связи несомненно будут способствовать дальнейшему социально-экономическому развитию наших стран, будут укреплять конкурентоспособность нашего объединения в мировой экономике и в конечном счёте обеспечат рост благосостояния населения наших стран. Евразийская интеграция доказывает свою эффективность: взаимный товарооборот стран-участниц вырос почти на двадцать миллиардов долларов, улучшилась инфраструктура торговли, возросла доля товаров с высокой добавленной стоимостью и сократилась доля сырья, причём сократилась значительно – с 40 до 28,9 процента. На 2015–2016 годы в рамках Евразийского союза согласованы общие макроэкономические ориентиры роста, запланирован комплекс мер по стимулированию хозяйственного развития, углублению сотрудничества в реальном секторе и улучшению делового климата. Предлагаем подумать над возможностью более тесного взаимодействия в сфере монетарной политики. Убеждён, действуя слаженно, центробанки наших стран могли бы эффективнее противостоять негативному влиянию резких колебаний курсов валют. Мы прекрасно отдаём себе отчёт в том, что это дело будущего. Здесь никто не собирается забегать вперёд. Согласованные действия монетарной политики должны быть основаны на интеграционных процессах в экономической прежде всего сфере после достижения определённого уровня взаимодействия. Обсуждать эти вопросы, говорить, думать об этом – всё это можно делать уже сейчас. В завершающей стадии находится работа по созданию общего рынка энергоресурсов Евразийского союза. На наше утверждение представлена концепция единого рынка электроэнергетики, который начнёт функционировать с 2019 года. Этот документ определяет этапы формирования, механизмы регулирования, порядок взаимной торговли электроэнергией. Продолжается формирование общего транспортного пространства Евразийского союза. Нам предстоит утвердить программу поэтапной либерализации рынка автомобильных грузоперевозок. Ставится задача сократить транспортные издержки, развить добросовестную конкуренцию в данном секторе услуг. Будет обеспечена гармонизация правил и требований для автоперевозчиков. По линии национальных корпораций развития разрабатываются совместные программы кредитования экспортёров на внешних рынках. Это поможет выправить недавний спад в нашей торговле с третьими странами. Идёт создание евразийской системы «единого окна» для бизнеса. Её запуск позволит унифицировать фискальные, таможенные и административные процедуры внешнеэкономической деятельности. До конца года нам предстоит серьёзно обновить договорно-правовую базу: в работе находятся более 50 проектов документов. Нужно, в частности, принять новый Таможенный кодекс, подписать соглашение о взаимодействии в валютно-финансовой и социально-экономической сферах. Завершить работу по большинству документов необходимо к следующему заседанию совета – это октябрь, в Астане. Интерес к углублению отношений с союзом проявляют и зарубежные партнёры. Налажено взаимодействие со структурами ООН. В сентябре на 70-й сессии Генеральной Ассамблеи ООН Евразийский экономический союз должен получить статус наблюдателя. Важно, чтобы наши внешнеполитические ведомства координировали усилия при рассмотрении в ООН соответствующей заявки. Евразийская экономическая комиссия ведёт переговоры по соглашениям по свободной торговле с рядом государств. Согласован и будет подписан в ближайшее время договор с Вьетнамом, аналогичные документы прорабатываются на экспертном уровне с Израилем, Индией, Египтом. Перспективным представляется развитие экономического сотрудничества Евразийского союза с Китайской Народной Республикой, говорил об этом сегодня и на встрече с Председателем КНР Си Цзиньпином. Кстати говоря, Председатель КНР также проявляет к этому интерес и говорит о том, что этот процесс вполне можно было бы вписать в «Экономический пояс так называемого Шёлкового пути» – проект, который продвигается нашими друзьями в Китае. Считаю целесообразным поручить Евразийской комиссии начать переговоры с КНР о заключении соглашения с КНР о торгово-экономическом сотрудничестве. На перспективу, думаю, стоит подумать над возможностью гармоничного совмещения Евразийской экономической интеграции и, как я уже сказал, китайской инициативы «Экономического пояса Шёлкового пути». Убеждён, тесная кооперация с китайскими партнёрами будет способствовать притоку инвестиций в государства союза, поможет создать новые рабочие места, эффективнее освоить евразийский транспортный потенциал. Я хочу вас поблагодарить за внимание и передаю слова Александру Григорьевичу Лукашенко, Президенту Беларуси, которая председательствует в этом году в Евразийском экономическом союзе. | I7: http://www.kremlin.ru/catalog/persons/119/events/49435 | J7: 15 | K7: 0 | L7: 6 | M7: 0 | N7: 0 | O7: 10 | P7: 0
A8: Россия | B8: 2015 | C8: 16 октября | E8: Путин | F8: заседание ВЕЭС | G8: Астана | I8: нет полного текста речи | J8: - | L8: - | M8: - | N8: - | O8: - | P8: -
A9: Россия | B9: 2015 | C9: 21 декабря | E9: Путин | F9: заседание ВЕЭС | G9: Москва | I9: нет полного текста речи | J9: - | L9: - | M9: - | N9: - | O9: - | P9: -
A10: Россия | B10: 2016 | C10: 26 декабря | D10: в узком составе | E10: Путин | F10: заседание ВЕЭС | G10: Санкт-Петербург | H10: В.Путин: Уважаемые коллеги! Я на правах хозяина несколько слов скажу, а потом передам слово Нурсултану Абишевичу, который возглавляет Высший Евразийский экономический совет, Казахстан у нас в этом году его возглавляет. Но прежде чем мы начнём работать, хочу вас всех поприветствовать в Петербурге. Евразийскому экономическому союзу исполняется два года, поэтому у нас есть хороший повод подвести итоги совместной работы за этот период и обменяться мнениями о перспективах дальнейшего развития евразийской интеграции. В процессе строительства Евразийского экономического союза мы вместе добились действительно серьёзных успехов. Создан ёмкий общий рынок, действующий по согласованным правилам, основанным на универсальных принципах Всемирной торговой организации, заметно повысились показатели и взаимной торговли. Последовательно устраняются барьеры на пути свободного движения товаров, услуг, рабочей силы и капитала. За время функционирования союза число нетарифных ограничений сокращено более чем на 30 процентов. В этом году заработал единый рынок лекарственных средств и медицинских изделий. Это поможет снизить цены на социально важную фармацевтическую продукцию, а также позволит усилить контроль за её качеством и порядком обращения. Эффективнее станет и борьба с контрафактом. В рамках Союза приняты Концепции формирования к 2025 году общих рынков газа, нефти и нефтепродуктов. Разрабатываются универсальные правила торговли электроэнергией и доступа к услугам субъектов естественных монополий в этой области. Ведётся совершенствование союзных правил регулирования в антимонопольной сфере. Продолжается работа над созданием к 2025 году общего финансового рынка. Согласованный экспертами проект Концепции поэтапной либерализации этого сектора экономики предусматривает гармонизацию действующих в наших странах правил осуществления кредитно-денежных, валютных, банковских, страховых операций. Последовательно совершенствуется и договорно-правовая база Евразийского экономического союза. Мы многое сделали по подготовке нового Таможенного кодекса. В Кодекс заложен целый ряд важных правовых нововведений, отвечающих самой передовой мировой практике. Заметно возрастают полномочия Евразийской комиссии по вопросам таможенного регулирования, предусматривается широкое использование цифровых технологий при проведении процедур оформления товаров на внешних границах Союза. Одним из ключевых приоритетов деятельности Евразийского экономического союза становится формирование благоприятной деловой среды для полноценного раскрытия имеющегося у наших стран производственного и технологического потенциала. Необходимо активнее содействовать предприятиям наших стран в развитии промышленной кооперации, энергичнее вовлекать в производственные и технологические цепочки малый и средний бизнес. Первоочередной задачей на ближайшую перспективу видится формирование единого цифрового пространства Евразийского экономического союза. Недавно подробно мы у себя, в Москве, обсуждали с Председателем Коллегии Евразийской комиссии Тиграном Суреновичем Саркисяном эту тему. И я с ним полностью согласен, в последние годы цифровая экономика получила широкое распространение, прежде всего в таких странах, как Китай, Соединённые Штаты, и отставание государств Евразийского союза в области глобальной электронной торговли и межотраслевых цифровых платформ может сказаться на нашей конкурентоспособности как на внешних, так и на внутренних рынках самого Союза. Я в детали здесь вдаваться не буду. Хочу отметить только, что у нас развивается и на внешнем контуре интересная и плодотворная работа с нашими возможными партнёрами. С Вьетнамом, как вы знаете, уже достигнуто Соглашение о свободной торговле. Интересуются таким же развитием отношений с нами Израиль, Индия, Иран, Сингапур, Египет. У нас ведётся работа и с Китайской Народной Республикой. Но всё это мы вместе с вами сможем сегодня обсудить. Я хочу вас всех ещё раз сердечно поприветствовать в Петербурге. Спасибо большое. <…> | I10: http://www.kremlin.ru/events/president/news/53596 | J10: 10 | K10: 0 | L10: 8 | M10: 0 | N10: 0 | O10: 7 | P10: 0
A11: Россия | B11: 2016 | C11: 31 мая | D11: в расширенном составе | E11: Путин | F11: заседание ВЕЭС | G11: Астана | H11: В.Путин: Уважаемые коллеги! За полтора года работы Евразийского экономического союза нам действительно многое удалось сделать в продвижении этого масштабного интеграционного проекта, главное – с полным основанием можно констатировать, что союз состоялся как современная международная организация, нацеленная на решение конкретных задач экономического развития наших стран. После присоединения Армении и Киргизии евразийской «пятёркой» сформирован ёмкий общий рынок с населением более 182 миллионов человек, обеспечена преемственность в управлении интеграционными процессами со стороны наднационального органа союза – Евразийской экономической комиссии. С 1 февраля назначен новый состав её Коллегии, который без раскачки включился в работу. В соответствии с решаемыми задачами усовершенствована и структура самой Комиссии. Создана солидная договорно-правовая база, которая расширяется на основе согласованных нами планов. В развитие учредительного Договора о Евразийском экономическом союзе принято более 60 соглашений. По ряду направлений работу необходимо продолжать и далее в таком же активном темпе. Это касается, в частности, подготовки нового Таможенного кодекса и Соглашения о порядке заключения союзом международных договоров, то есть дальнейшее продвижение интеграции зависит от своевременного принятия необходимых для нашего развития нормативных документов. Многого удалось достичь в деле сокращения взаимных барьеров на пути свободного движения товаров, рабочей силы, услуг и капитала. Не могу не согласиться с коллегами, которые выступали по поводу того, что их ещё очень много. Напомню только, что из выявленных на этапе подготовки Договора о союзе 422 торговых ограничений более 80 уже устранено, ещё около 30 находятся в процессе отмены, а 16 должны быть ликвидированы в течение текущего, 2016 года. Крайне важно продолжить унификацию нетарифного регулирования, развивать механизмы отслеживания движения товаров от момента их ввоза на таможенную территорию союза до их передачи потребителю, совершенствовать взаимодействие в сфере санитарно-эпидемиологического контроля. Необходимо и далее уделять приоритетное внимание проведению согласованной политики в ключевых секторах экономики, а также гармонизации законодательства в области естественных монополий. Перспективным видится подключение государств союза к программе импортозамещения, проводимой в России. Мы приглашаем всех наших партнёров к совместному производству оборудования и комплектующих более чем в 25 отраслях, включая машиностроение, электронную и лёгкую промышленность, сельское хозяйство. К 2019 году должен быть сформирован общий рынок электроэнергии, утверждена его концепция, начата подготовка соответствующей программы. По оценкам экспертов, реализация этой задачи обеспечит дополнительный прирост ВВП государств – членов союза в размере 7 миллиардов долларов. Сегодня мы сделаем очередной шаг к созданию к 2025 году единого рынка углеводородов, о чём мы с вами очень много говорили и спорили в своё время, примем соответствующие документы, которые предусматривают равные условия конкуренции на территории всего союза, что даст совокупный эффект в газовой отрасли более 1 миллиарда долларов, а в нефтяной – до 8 миллиардов в год. Уже в текущем году заработает общий рынок в социально значимой сфере лекарственных средств и медицинских изделий. На завершающем этапе находится согласование договорённостей о правилах и принципах обращения этой продукции. Поступательно развивается наше сотрудничество в инновационной сфере. Создаётся Евразийский инжиниринговый центр по станкостроению, совместно разрабатываются евразийские технологические платформы. Неотъемлемой составляющей интеграционного процесса является либерализация торговли услугами. В текущем году предстоит принять дорожные карты по унификации законодательства в области строительства и проектирования, проведения научных исследований, а также в туризме. Единые правила уже охватывают 43 сервисных сектора, или более 50 процентов от общего объёма производимых в Союзе услуг. Весьма перспективной представляется идея создания единого информационного пространства. Предложили бы Комиссии подготовить соображения на этот счёт. Эффективному функционированию интеграционного объединения способствует системное выстраивание отношений с внешними партнёрами. Мы поддерживаем предложение казахстанского председательства сконцентрировать усилия на дальнейшем углублении экономических связей Союза с другими странами и интеграционными объединениями, в первую очередь с государствами Шанхайской организации сотрудничества и АСЕАН. На этом направлении уже сделано немало. Создана зона свободной торговли с Вьетнамом, готовится перечень конкретных проектов в развитие идеи сопряжения Евразийского экономического союза с китайской инициативой «Шёлкового пути». Евразийской комиссией подписаны меморандумы о взаимопонимании с правительствами Монголии, Перу, Чили. В планах – разработка торговых договорённостей с Сербией. Готовятся соглашения о сотрудничестве с Южной Кореей, Эквадором и МЕРКОСУР. Интерес к установлению тесных связей с союзом проявляют Иран, Индия, Египет, Израиль. Приветствуем также инициативу казахстанских партнёров о проведении международной конференции по налаживанию взаимодействия между Евразийским союзом и ЕС. Необходимо, чтобы Евразийская экономическая комиссия активно подключилась к её проработке. И ещё хотел бы отметить большую практическую поддержку, которую оказывает созданный год назад Евразийский деловой совет. Считаю это направление тоже чрезвычайно важным. Недавно его возглавил Виктор Борисович Христенко, имеющий хороший опыт работы в наших интеграционных структурах. И в заключение, пользуясь возможностью, хотел бы пригласить всех вас, как мы в узком составе договорились, провести нашу следующую встречу в декабре, по традиции, в Москве. Спасибо за внимание. | I11: http://www.kremlin.ru/catalog/persons/119/events/52049 | J11: 11 | K11: 0 | L11: 11 | M11: 0 | N11: 0 | O11: 19 | P11: 1
A12: Россия | B12: 2017 | C12: 14 апреля | E12: Путин | G12: Бишкек | H12: В.Путин: Уважаемые коллеги! Уважаемый Председатель! Прежде всего хочу, так же как и присутствующие здесь главы государств, искренне поприветствовать Президента Молдавии Игоря Николаевича Додона, который впервые участвует в заседании Высшего Евразийского экономического совета. На заседании Высшего Евразийского экономического совета. На заседании Высшего Евразийского экономического совета. Отмечу, что сотрудничество в рамках ЕАЭС продвигается успешно. Мы вместе добились результатов в деле формирования и укрепления ёмкого общего рынка с универсальными правилами для экономических операторов. Можно с полной уверенностью сказать, что наш общий рынок сработал в качестве своеобразной подушки безопасности, несмотря на определённые издержки, связанные с внешней конъюнктурой, которая сложилась неблагоприятно (об этом уже было здесь сказано). Тем не менее как подушка безопасности наши интеграционные институты сработали, в определённой степени нивелировали воздействие неблагоприятной внешней конъюнктуры, а национальные экономики смогли адаптироваться к новым реалиям. Это действительно так. Обращаю внимание, что в январе текущего года по сравнению с январём прошлого года объём взаимной торговли в рамках союза вырос на 38 процентов. Как Нурсултан Абишевич говорил, кризисы приходят, но они рано или поздно заканчиваются. 38 процентов у нас плюс, а поставки государств-членов в третьи страны выросли на 37 процентов. Существенно улучшилась (и это отмечаю как, наверное, самое главное) структура экспортно-импортных операций, снизился удельный вес сырья в торговле в 2016 году и обозначился рост доли машин, транспортных средств и оборудования, продовольственных и сельхозтоваров. В рамках ЕАЭС мы вместе добились результатов в деле формирования и укрепления ёмкого общего рынка с универсальными правилами для экономических операторов. В 2016 году производство в сфере сельского хозяйства союза увеличилось почти на четыре процента. Наметился рост в промышленности. Рассчитываем на позитивную динамику в этих отраслях и в текущем году. Отдельно хотел бы отметить, что существенная часть этого прироста приходится именно на российский рынок, который всё более активно осваивается государствами – членами ЕАЭС. Это выгодно как нашим партнёрам по союзу, так и российским потребителям. В 2016 году на Россию пришлось около 62 процентов объёма совокупных внутрисоюзных поставок. Во многом благодаря рынку союза в Казахстане развивается новая отрасль – автомобилестроение. Хочу проинформировать Нурсултана Абишевича: мы приняли решение по Вашему предложению о продолжении расширения нашего сотрудничества в космосе с использованием Байконура. Мы все наши планы скорректируем в самое ближайшее время, имею в виду использование космодрома Восточный, с тем, чтобы активно вместе с вами работать по имеющимся у нас проектам, которые вы сформулировали. С использованием не только Байконура на длительную перспективу, но и с реализацией тех планов по совместным пускам, по разработке новых видов ракетно-космической техники. Шагом к укреплению ЕАЭС является сопряжение информационных систем наших госорганов, прежде всего таможенных служб, с целью создания механизма мониторинга движения товаров по территории союза. В Киргизии создаются условия для восстановления текстильного и швейного производства. Как известно, в 2016 году экспорт киргизских товаров лёгкой промышленности в страны союза вырос на 38 процентов. Товарооборот сельхозпродукции между Арменией, скажем, и Россией также увеличился, причём на солидную величину – в 22 процента. Развивается кооперация с Республикой Беларусь, причём развивается очень активно. По некоторым крупным предприятиям взаимная зависимость составляет сейчас 40 и более процентов. Многие виды товаров, произведённые в Белоруссии, рассматриваются в Российской Федерации как производство отечественного производителя и пользуются такими же льготами при государственных закупках на территории Российской Федерации. В последнее время проделана значительная работа по совершенствованию договорно-правовой базы союза: согласованы такие фундаментальные документы, как Таможенный кодекс, Концепция формирования общих рынков газа, нефти и нефтепродуктов, поэтапной либерализации финансового рынка. По всем этим направлениям удалось выйти на взаимоприемлемые решения. Приоритетное внимание необходимо уделять дальнейшей работе по улучшению макроэкономической ситуации, увеличению объёмов инвестиций в основной капитал, созданию большей добавленной стоимости и развитию несырьевого экспорта. Российский рынок всё более активно осваивается государствами – членами ЕАЭС. Это выгодно как нашим партнёрам по союзу, так и российским потребителям. Важную роль в решении актуальных вопросов экономического роста, обеспечения финансовой стабильности наших стан играет Евразийский банк развития и управляемый им Евразийский фонд стабилизации и развития. Банк выполняет значимую роль в осуществлении крупных инвестиционных инициатив. На реализацию этих целей уже предусмотрено около четырёх миллиардов долларов. Последний пример такого сотрудничества – недавно подписанное соглашение о предоставлении Киргизской Республике кредита на сумму 110 миллионов долларов для финансирования конкретных инфраструктурных проектов в республике. Одной из насущных задач является последовательное устранение препятствий на пути свободного движения товаров, рабочей силы, услуг и капиталов. Такие барьеры у нас ещё, к сожалению, сохраняются, но мы договорились о том, что постепенно будем их устранять. В соответствии с Договором о союзе эти процессы будут планомерно реализовываться до 2025 года. Ещё одним шагом к укреплению ЕАЭС является сопряжение информационных систем наших госорганов, прежде всего таможенных служб, с целью создания механизма мониторинга движения товаров по территории союза. Это позволило бы либерализовать и улучшить решение таких проблемных вопросов для транзита товаров третьих стран, в том числе и Украины. Мы об этом с вами дискутировали неоднократно и пришли к выводу, что введение этой электронной системы отслеживания движения товаров помогло бы и нашим партнёрам, которые находятся вне союза. Проделана значительная работа по совершенствованию договорно-правовой базы союза: согласованы такие фундаментальные документы, как Таможенный кодекс, Концепция формирования общих рынков газа, нефти и нефтепродуктов, поэтапной либерализации финансового рынка. Эффективный контроль невозможен без внедрения обязательного оформления товаросопроводительных документов в электронной форме. Это передовая мировая практика. С учётом технических особенностей подобных проектов необходимо в максимально короткий срок завершить подготовку соответствующего соглашения. Если говорить о международной деятельности союза, напомню, что уже действует соглашение о свободной торговле с Вьетнамом, ведутся переговоры с Китайской Народной Республикой, Израилем, Сербией, Египтом, Индией, Сингапуром, и уже упоминалось здесь о наших контактах и соответствующей работе с Ираном. Мы также контактируем активно с Шанхайской организацией сотрудничества, АСЕАН и другими организациями. Развитие внешнего контура нашего интеграционного объединения должно быть продолжено на системной и плановой основе. В заключение хотел бы сказать и выразить надежду, что Евразийский союз продолжит крепнуть и расти на благо народов наших стран. Думаю, что у нас есть все основания для такого оптимизма. Спасибо большое за внимание. | I12: http://www.kremlin.ru/events/president/transcripts/54293 | J12: 6 | K12: 1 | L12: 14 | M12: 0 | N12: 0 | O12: 21 | P12: 0
A13: Россия | B13: 2017 | C13: 11 октября | D13: в расширенном составе | E13: Путин | F13: заседание ВЕЭС | G13: Сочи | H13: В.Путин: Уважаемые коллеги! Рад вас всех ещё раз поприветствовать на нашей встрече, и в том числе нашего гостя – Президента Молдавии Игоря Николаевича Додона. Только что в узком составе мы обсудили текущие вопросы деятельности Евразийского экономического союза, подвели некоторые итоги интеграционной работы и приняли ряд важных решений. Можно с уверенностью сказать, что союз успешно функционирует и развивается. Интеграция положительно сказывается на темпах экономического роста наших государств. Совокупный ВВП Евразийского экономического союза увеличился в текущем году на 1,8 процента. Позитивная динамика фиксируется в стратегических производственных отраслях: в промышленности рост составил 2,4 процента, в сельском хозяйстве – почти 1 процент, расширились грузовые, пассажирские перевозки соответственно на 6,9 и на 7,8 процента. Возросли объёмы внешней торговли союза – плюс 26 процентов, а положительное сальдо экспортно-импортных операций превысило 77 миллиардов долларов. При этом доля машин, оборудования и транспортных средств достигла 17,5 процента. Удельный же вес энергетических товаров снизился до 28 процентов. Товарооборот между государствами – членами Евразийского экономического союза увеличился в текущем году на 30 процентов. Товарооборот между государствами – членами Евразийского экономического союза увеличился в текущем году на 30 процентов. Это прямое следствие того, что мы создали в рамках союза единый рынок и общее экономическое пространство. Убеждены, нужно продолжать системную работу по устранению ограничений, мешающих свободному передвижению товаров, рабочей силы, услуг и капитала между нашими государствами. Следует ускорить разработку дорожной карты по ликвидации имеющихся пока ещё барьеров в сфере промышленности, агропромышленном комплексе, энергетике, техническом регулировании. Государствам – членам Союза предстоит завершить все внутренние процедуры, чтобы, как запланировано, с 1 января будущего года вступил в силу новый Таможенный кодекс Евразийского экономического союза. В свою очередь, Евразийская экономическая комиссия должна заранее принять технические решения, необходимые для практического применения кодекса во внутрисоюзной торговле. Государствам – членам Союза предстоит завершить все внутренние процедуры, чтобы с 1 января будущего года вступил в силу новый Таможенный кодекс ЕАЭС. В ходе заседания в узком составе мы также утвердили новый важный документ, который называется «Основные направления цифровой повестки Союза до 2025 года». Напомню, инициатива его разработки была выдвинута на заседании нашего Союза ещё в декабре прошлого года. Россия готова активно участвовать в практической реализации цифровой повестки. Речь идёт о проведении согласованной со странами Союза политики в области развития интернет-экономики, формирования общих правил цифровой торговли, единых стандартов обмена информацией и её защиты. Отмечу, принимаемые нами сегодня решения о налаживании сотрудничества в области космических и геоинформационных услуг, а также об объединении действующих в государствах Евразийского экономического союза национальных систем дистанционного зондирования Земли также являются одним из очень важных наших решений. В числе ключевых задач видим совершенствование кредитно-финансовой инфраструктуры Евразийского экономического союза. Предлагаем эффективнее задействовать потенциал Евразийского банка развития и Евразийского фонда стабилизации для обеспечения роста экономик наших стран, использовать специальные инвестиционные механизмы Евразийского банка и Стабфонда для укрепления финансовой устойчивости государств – членов Союза. В числе ключевых задач видим совершенствование кредитно-финансовой инфраструктуры ЕАЭС. Предлагаем эффективнее задействовать потенциал Евразийского банка развития и Евразийского фонда стабилизации. Особого внимания, как представляется, требуют вопросы, связанные с продвижением позиций Евразийского экономического союза на международной арене, развитием связи нашего объединения с другими государствами. В этом контексте считаем важным налаживать более тесную кооперацию с партнёрами из СНГ, которые не входят в Евразийский экономический союз. Мы сегодня достаточно подробно говорили об этом и о том, что нам нужно утвердить статус наблюдателя. Стоит ускорить и уже начатый переговорный процесс о создании зон свободной торговли с теми странами, с которыми договорились выстраивать такую работу и с которыми Комиссия уже ведёт работу. Большое значение придаём подготовке проекта соглашений о сотрудничестве между Евразийским экономическим союзом и этими странами. В заключение хотел бы высказать признательность киргизским друзьям за большую работу, проделанную в ходе председательства Киргизии в органах Евразийского экономического союза в текущем году. В качестве следующего председателя Россия готова к интенсивному взаимодействию со всеми партнёрами по союзу в целях дальнейшего укрепления нашего интеграционного объединения. Позвольте передать слово Президенту Армении Сержу Азатовичу Саргсяну. В.Путин: Уважаемые коллеги! Хочу всех вас поблагодарить за сегодняшнюю достаточно конструктивную, содержательную работу. В узком составе мы дискутировали практически по всем вопросам, глубоко погружались во все проблемы. Надеюсь, что такая же содержательная работа сохранится в будущем. Хочу пожелать Комиссии, всем нашим коллегам, которые занимаются работой в рамках нашего объединения, в рамках нашего союза, так же интенсивно работать в будущем. Россия берёт на себя обязанности председателя в следующем году. Заверяю вас, что мы будем делать всё, что от нас зависит, чтобы наше объединение развивалось, и развивалось успешно. Нурсултан Абишевич сегодня предложил созвать и внеочередной саммит, посвящённый развитию цифровых технологий, цифровой экономики. Мы все это поддержали. Согласуем с Казахстаном время, место, с удовольствием примем участие. | I13: http://www.kremlin.ru/events/president/news/55819 | J13: 17 | K13: 0 | L13: 9 | M13: 0 | N13: 0 | O13: 6 | P13: 0
